2019-02-28 06:39:55,604 [Dummy-1:123145319063552] [django.db.backends:111] [utils:execute] [DEBUG]- (0.001) 
            SELECT name, type FROM sqlite_master
            WHERE type in ('table', 'view') AND NOT name='sqlite_sequence'
            ORDER BY name; args=None
2019-02-28 06:40:09,611 [Dummy-1:123145335394304] [django.db.backends:111] [utils:execute] [DEBUG]- (0.000) 
            SELECT name, type FROM sqlite_master
            WHERE type in ('table', 'view') AND NOT name='sqlite_sequence'
            ORDER BY name; args=None
2019-02-28 06:42:30,368 [Thread-2:123145340649472] [blog.views:12] [views:index] [ERROR]- [Errno 2] No such file or directory: 'sss.txt'
2019-02-28 06:42:30,376 [Thread-2:123145340649472] [django.server:154] [basehttp:log_message] [INFO]- "GET / HTTP/1.1" 200 14952
2019-02-28 06:42:30,401 [Thread-4:123145351159808] [django.template:872] [base:_resolve_lookup] [DEBUG]- Exception while resolving variable 'name' in template 'unknown'.
Traceback (most recent call last):
  File "/Users/gsy/.virtualenvs/test/lib/python3.7/site-packages/django/core/handlers/exception.py", line 34, in inner
    response = get_response(request)
  File "/Users/gsy/.virtualenvs/test/lib/python3.7/site-packages/django/core/handlers/base.py", line 111, in _get_response
    resolver_match = resolver.resolve(request.path_info)
  File "/Users/gsy/.virtualenvs/test/lib/python3.7/site-packages/django/urls/resolvers.py", line 520, in resolve
    raise Resolver404({'tried': tried, 'path': new_path})
django.urls.exceptions.Resolver404: {'tried': [[<URLResolver <URLPattern list> (admin:admin) 'admin/'>], [<URLPattern '' [name='index']>]], 'path': 'js/jquery.min.js'}

During handling of the above exception, another exception occurred:

Traceback (most recent call last):
  File "/Users/gsy/.virtualenvs/test/lib/python3.7/site-packages/django/template/base.py", line 829, in _resolve_lookup
    current = current[bit]
TypeError: 'URLResolver' object is not subscriptable

During handling of the above exception, another exception occurred:

Traceback (most recent call last):
  File "/Users/gsy/.virtualenvs/test/lib/python3.7/site-packages/django/template/base.py", line 837, in _resolve_lookup
    current = getattr(current, bit)
AttributeError: 'URLResolver' object has no attribute 'name'

During handling of the above exception, another exception occurred:

Traceback (most recent call last):
  File "/Users/gsy/.virtualenvs/test/lib/python3.7/site-packages/django/template/base.py", line 843, in _resolve_lookup
    current = current[int(bit)]
ValueError: invalid literal for int() with base 10: 'name'

During handling of the above exception, another exception occurred:

Traceback (most recent call last):
  File "/Users/gsy/.virtualenvs/test/lib/python3.7/site-packages/django/template/base.py", line 850, in _resolve_lookup
    (bit, current))  # missing attribute
django.template.base.VariableDoesNotExist: Failed lookup for key [name] in <URLResolver <URLPattern list> (admin:admin) 'admin/'>
2019-02-28 06:42:30,403 [Thread-2:123145340649472] [django.server:154] [basehttp:log_message] [WARNING]- "GET /static/css/base.css HTTP/1.1" 404 1660
2019-02-28 06:42:30,407 [Thread-5:123145356414976] [django.template:872] [base:_resolve_lookup] [DEBUG]- Exception while resolving variable 'name' in template 'unknown'.
Traceback (most recent call last):
  File "/Users/gsy/.virtualenvs/test/lib/python3.7/site-packages/django/core/handlers/exception.py", line 34, in inner
    response = get_response(request)
  File "/Users/gsy/.virtualenvs/test/lib/python3.7/site-packages/django/core/handlers/base.py", line 111, in _get_response
    resolver_match = resolver.resolve(request.path_info)
  File "/Users/gsy/.virtualenvs/test/lib/python3.7/site-packages/django/urls/resolvers.py", line 520, in resolve
    raise Resolver404({'tried': tried, 'path': new_path})
django.urls.exceptions.Resolver404: {'tried': [[<URLResolver <URLPattern list> (admin:admin) 'admin/'>], [<URLPattern '' [name='index']>]], 'path': 'js/sliders.js'}

During handling of the above exception, another exception occurred:

Traceback (most recent call last):
  File "/Users/gsy/.virtualenvs/test/lib/python3.7/site-packages/django/template/base.py", line 829, in _resolve_lookup
    current = current[bit]
TypeError: 'URLResolver' object is not subscriptable

During handling of the above exception, another exception occurred:

Traceback (most recent call last):
  File "/Users/gsy/.virtualenvs/test/lib/python3.7/site-packages/django/template/base.py", line 837, in _resolve_lookup
    current = getattr(current, bit)
AttributeError: 'URLResolver' object has no attribute 'name'

During handling of the above exception, another exception occurred:

Traceback (most recent call last):
  File "/Users/gsy/.virtualenvs/test/lib/python3.7/site-packages/django/template/base.py", line 843, in _resolve_lookup
    current = current[int(bit)]
ValueError: invalid literal for int() with base 10: 'name'

During handling of the above exception, another exception occurred:

Traceback (most recent call last):
  File "/Users/gsy/.virtualenvs/test/lib/python3.7/site-packages/django/template/base.py", line 850, in _resolve_lookup
    (bit, current))  # missing attribute
django.template.base.VariableDoesNotExist: Failed lookup for key [name] in <URLResolver <URLPattern list> (admin:admin) 'admin/'>
2019-02-28 06:42:30,408 [Thread-3:123145345904640] [django.server:154] [basehttp:log_message] [WARNING]- "GET /static/css/index.css HTTP/1.1" 404 1663
2019-02-28 06:42:30,411 [Thread-6:123145361670144] [django.template:872] [base:_resolve_lookup] [DEBUG]- Exception while resolving variable 'name' in template 'unknown'.
Traceback (most recent call last):
  File "/Users/gsy/.virtualenvs/test/lib/python3.7/site-packages/django/core/handlers/exception.py", line 34, in inner
    response = get_response(request)
  File "/Users/gsy/.virtualenvs/test/lib/python3.7/site-packages/django/core/handlers/base.py", line 111, in _get_response
    resolver_match = resolver.resolve(request.path_info)
  File "/Users/gsy/.virtualenvs/test/lib/python3.7/site-packages/django/urls/resolvers.py", line 520, in resolve
    raise Resolver404({'tried': tried, 'path': new_path})
django.urls.exceptions.Resolver404: {'tried': [[<URLResolver <URLPattern list> (admin:admin) 'admin/'>], [<URLPattern '' [name='index']>]], 'path': 'js/nav.js'}

During handling of the above exception, another exception occurred:

Traceback (most recent call last):
  File "/Users/gsy/.virtualenvs/test/lib/python3.7/site-packages/django/template/base.py", line 829, in _resolve_lookup
    current = current[bit]
TypeError: 'URLResolver' object is not subscriptable

During handling of the above exception, another exception occurred:

Traceback (most recent call last):
  File "/Users/gsy/.virtualenvs/test/lib/python3.7/site-packages/django/template/base.py", line 837, in _resolve_lookup
    current = getattr(current, bit)
AttributeError: 'URLResolver' object has no attribute 'name'

During handling of the above exception, another exception occurred:

Traceback (most recent call last):
  File "/Users/gsy/.virtualenvs/test/lib/python3.7/site-packages/django/template/base.py", line 843, in _resolve_lookup
    current = current[int(bit)]
ValueError: invalid literal for int() with base 10: 'name'

During handling of the above exception, another exception occurred:

Traceback (most recent call last):
  File "/Users/gsy/.virtualenvs/test/lib/python3.7/site-packages/django/template/base.py", line 850, in _resolve_lookup
    (bit, current))  # missing attribute
django.template.base.VariableDoesNotExist: Failed lookup for key [name] in <URLResolver <URLPattern list> (admin:admin) 'admin/'>
2019-02-28 06:42:30,415 [Thread-7:123145366925312] [django.template:872] [base:_resolve_lookup] [DEBUG]- Exception while resolving variable 'name' in template 'unknown'.
Traceback (most recent call last):
  File "/Users/gsy/.virtualenvs/test/lib/python3.7/site-packages/django/core/handlers/exception.py", line 34, in inner
    response = get_response(request)
  File "/Users/gsy/.virtualenvs/test/lib/python3.7/site-packages/django/core/handlers/base.py", line 111, in _get_response
    resolver_match = resolver.resolve(request.path_info)
  File "/Users/gsy/.virtualenvs/test/lib/python3.7/site-packages/django/urls/resolvers.py", line 520, in resolve
    raise Resolver404({'tried': tried, 'path': new_path})
django.urls.exceptions.Resolver404: {'tried': [[<URLResolver <URLPattern list> (admin:admin) 'admin/'>], [<URLPattern '' [name='index']>]], 'path': 'images/a1.jpg'}

During handling of the above exception, another exception occurred:

Traceback (most recent call last):
  File "/Users/gsy/.virtualenvs/test/lib/python3.7/site-packages/django/template/base.py", line 829, in _resolve_lookup
    current = current[bit]
TypeError: 'URLResolver' object is not subscriptable

During handling of the above exception, another exception occurred:

Traceback (most recent call last):
  File "/Users/gsy/.virtualenvs/test/lib/python3.7/site-packages/django/template/base.py", line 837, in _resolve_lookup
    current = getattr(current, bit)
AttributeError: 'URLResolver' object has no attribute 'name'

During handling of the above exception, another exception occurred:

Traceback (most recent call last):
  File "/Users/gsy/.virtualenvs/test/lib/python3.7/site-packages/django/template/base.py", line 843, in _resolve_lookup
    current = current[int(bit)]
ValueError: invalid literal for int() with base 10: 'name'

During handling of the above exception, another exception occurred:

Traceback (most recent call last):
  File "/Users/gsy/.virtualenvs/test/lib/python3.7/site-packages/django/template/base.py", line 850, in _resolve_lookup
    (bit, current))  # missing attribute
django.template.base.VariableDoesNotExist: Failed lookup for key [name] in <URLResolver <URLPattern list> (admin:admin) 'admin/'>
2019-02-28 06:42:30,417 [Thread-8:123145372180480] [django.template:872] [base:_resolve_lookup] [DEBUG]- Exception while resolving variable 'name' in template 'unknown'.
Traceback (most recent call last):
  File "/Users/gsy/.virtualenvs/test/lib/python3.7/site-packages/django/core/handlers/exception.py", line 34, in inner
    response = get_response(request)
  File "/Users/gsy/.virtualenvs/test/lib/python3.7/site-packages/django/core/handlers/base.py", line 111, in _get_response
    resolver_match = resolver.resolve(request.path_info)
  File "/Users/gsy/.virtualenvs/test/lib/python3.7/site-packages/django/urls/resolvers.py", line 520, in resolve
    raise Resolver404({'tried': tried, 'path': new_path})
django.urls.exceptions.Resolver404: {'tried': [[<URLResolver <URLPattern list> (admin:admin) 'admin/'>], [<URLPattern '' [name='index']>]], 'path': 'images/a2.jpg'}

During handling of the above exception, another exception occurred:

Traceback (most recent call last):
  File "/Users/gsy/.virtualenvs/test/lib/python3.7/site-packages/django/template/base.py", line 829, in _resolve_lookup
    current = current[bit]
TypeError: 'URLResolver' object is not subscriptable

During handling of the above exception, another exception occurred:

Traceback (most recent call last):
  File "/Users/gsy/.virtualenvs/test/lib/python3.7/site-packages/django/template/base.py", line 837, in _resolve_lookup
    current = getattr(current, bit)
AttributeError: 'URLResolver' object has no attribute 'name'

During handling of the above exception, another exception occurred:

Traceback (most recent call last):
  File "/Users/gsy/.virtualenvs/test/lib/python3.7/site-packages/django/template/base.py", line 843, in _resolve_lookup
    current = current[int(bit)]
ValueError: invalid literal for int() with base 10: 'name'

During handling of the above exception, another exception occurred:

Traceback (most recent call last):
  File "/Users/gsy/.virtualenvs/test/lib/python3.7/site-packages/django/template/base.py", line 850, in _resolve_lookup
    (bit, current))  # missing attribute
django.template.base.VariableDoesNotExist: Failed lookup for key [name] in <URLResolver <URLPattern list> (admin:admin) 'admin/'>
2019-02-28 06:42:30,421 [Thread-4:123145351159808] [django.server:154] [basehttp:log_message] [WARNING]- "GET /js/jquery.min.js HTTP/1.1" 404 2107
2019-02-28 06:42:30,423 [Thread-5:123145356414976] [django.server:154] [basehttp:log_message] [WARNING]- "GET /js/sliders.js HTTP/1.1" 404 2098
2019-02-28 06:42:30,426 [Thread-6:123145361670144] [django.server:154] [basehttp:log_message] [WARNING]- "GET /js/nav.js HTTP/1.1" 404 2086
2019-02-28 06:42:30,428 [Thread-7:123145366925312] [django.server:154] [basehttp:log_message] [WARNING]- "GET /images/a1.jpg HTTP/1.1" 404 2098
2019-02-28 06:42:30,429 [Thread-8:123145372180480] [django.server:154] [basehttp:log_message] [WARNING]- "GET /images/a2.jpg HTTP/1.1" 404 2098
2019-02-28 06:42:30,434 [Thread-4:123145351159808] [django.template:872] [base:_resolve_lookup] [DEBUG]- Exception while resolving variable 'name' in template 'unknown'.
Traceback (most recent call last):
  File "/Users/gsy/.virtualenvs/test/lib/python3.7/site-packages/django/core/handlers/exception.py", line 34, in inner
    response = get_response(request)
  File "/Users/gsy/.virtualenvs/test/lib/python3.7/site-packages/django/core/handlers/base.py", line 111, in _get_response
    resolver_match = resolver.resolve(request.path_info)
  File "/Users/gsy/.virtualenvs/test/lib/python3.7/site-packages/django/urls/resolvers.py", line 520, in resolve
    raise Resolver404({'tried': tried, 'path': new_path})
django.urls.exceptions.Resolver404: {'tried': [[<URLResolver <URLPattern list> (admin:admin) 'admin/'>], [<URLPattern '' [name='index']>]], 'path': 'images/a4.jpg'}

During handling of the above exception, another exception occurred:

Traceback (most recent call last):
  File "/Users/gsy/.virtualenvs/test/lib/python3.7/site-packages/django/template/base.py", line 829, in _resolve_lookup
    current = current[bit]
TypeError: 'URLResolver' object is not subscriptable

During handling of the above exception, another exception occurred:

Traceback (most recent call last):
  File "/Users/gsy/.virtualenvs/test/lib/python3.7/site-packages/django/template/base.py", line 837, in _resolve_lookup
    current = getattr(current, bit)
AttributeError: 'URLResolver' object has no attribute 'name'

During handling of the above exception, another exception occurred:

Traceback (most recent call last):
  File "/Users/gsy/.virtualenvs/test/lib/python3.7/site-packages/django/template/base.py", line 843, in _resolve_lookup
    current = current[int(bit)]
ValueError: invalid literal for int() with base 10: 'name'

During handling of the above exception, another exception occurred:

Traceback (most recent call last):
  File "/Users/gsy/.virtualenvs/test/lib/python3.7/site-packages/django/template/base.py", line 850, in _resolve_lookup
    (bit, current))  # missing attribute
django.template.base.VariableDoesNotExist: Failed lookup for key [name] in <URLResolver <URLPattern list> (admin:admin) 'admin/'>
2019-02-28 06:42:30,439 [Thread-5:123145356414976] [django.template:872] [base:_resolve_lookup] [DEBUG]- Exception while resolving variable 'name' in template 'unknown'.
Traceback (most recent call last):
  File "/Users/gsy/.virtualenvs/test/lib/python3.7/site-packages/django/core/handlers/exception.py", line 34, in inner
    response = get_response(request)
  File "/Users/gsy/.virtualenvs/test/lib/python3.7/site-packages/django/core/handlers/base.py", line 111, in _get_response
    resolver_match = resolver.resolve(request.path_info)
  File "/Users/gsy/.virtualenvs/test/lib/python3.7/site-packages/django/urls/resolvers.py", line 520, in resolve
    raise Resolver404({'tried': tried, 'path': new_path})
django.urls.exceptions.Resolver404: {'tried': [[<URLResolver <URLPattern list> (admin:admin) 'admin/'>], [<URLPattern '' [name='index']>]], 'path': 'images/a3.jpg'}

During handling of the above exception, another exception occurred:

Traceback (most recent call last):
  File "/Users/gsy/.virtualenvs/test/lib/python3.7/site-packages/django/template/base.py", line 829, in _resolve_lookup
    current = current[bit]
TypeError: 'URLResolver' object is not subscriptable

During handling of the above exception, another exception occurred:

Traceback (most recent call last):
  File "/Users/gsy/.virtualenvs/test/lib/python3.7/site-packages/django/template/base.py", line 837, in _resolve_lookup
    current = getattr(current, bit)
AttributeError: 'URLResolver' object has no attribute 'name'

During handling of the above exception, another exception occurred:

Traceback (most recent call last):
  File "/Users/gsy/.virtualenvs/test/lib/python3.7/site-packages/django/template/base.py", line 843, in _resolve_lookup
    current = current[int(bit)]
ValueError: invalid literal for int() with base 10: 'name'

During handling of the above exception, another exception occurred:

Traceback (most recent call last):
  File "/Users/gsy/.virtualenvs/test/lib/python3.7/site-packages/django/template/base.py", line 850, in _resolve_lookup
    (bit, current))  # missing attribute
django.template.base.VariableDoesNotExist: Failed lookup for key [name] in <URLResolver <URLPattern list> (admin:admin) 'admin/'>
2019-02-28 06:42:30,441 [Thread-4:123145351159808] [django.server:154] [basehttp:log_message] [WARNING]- "GET /images/a4.jpg HTTP/1.1" 404 2098
2019-02-28 06:42:30,443 [Thread-5:123145356414976] [django.server:154] [basehttp:log_message] [WARNING]- "GET /images/a3.jpg HTTP/1.1" 404 2098
